<mujoco model="pendulum">
  <worldbody>
    <body name="base" pos="0 0 0">
      <!-- Dummy base inertia: for parser testing only -->
      <inertial pos="0 0 0" mass="2" diaginertia="1 1 1"/>
      <body name="pendulum_link" pos="0 0 1.5">
        <inertial pos="0 0 -0.5" mass="1" diaginertia="0.083433 0.083433 0.0002"/>
        <joint name="pendulum_joint" pos="0 0 0" axis="0 1 0" />
        <geom name="pendulum_link_visual" size="0.02 0.5" pos="0 0 -0.5" 
              type="cylinder" contype="0" conaffinity="0" group="1" density="0" 
              rgba="1 0 0 1"/>
      </body>
    </body>
  </worldbody>
  <actuator>
    <motor joint="pendulum_joint"/>
  </actuator>
</mujoco>
