<?xml version="1.0"?>

<robot name="pendulum">
  <mujoco>
    <compiler fusestatic="false" balanceinertia="true" discardvisual="false"/>
  </mujoco>

  <!-- nontrivial base link -->
  <link name="base">
    <inertial>
      <mass value="2"/>
      <origin rpy="0 0 0" xyz="0 0 0"/>
      <inertia ixx="0.00072" ixy="0" ixz="0" iyy="0.00072" iyz="0" izz="0.00072"/>
    </inertial>
    <visual name="base_visual">
      <origin rpy="0 0 0" xyz="0 0 0"/>
      <geometry>
        <sphere radius="0.03"/>
      </geometry>
    </visual>
  </link>

  <!-- pendulum link -->
  <link name="pendulum_link">
    <visual name="pendulum_link_visual">
      <origin rpy="0 0 0" xyz="0 0 -0.5"/>
      <geometry>
        <capsule length="1.0" radius="0.02"/>
      </geometry>
    </visual>
    <collision name="pendulum_link_collision">
      <origin rpy="0 0 0" xyz="0 0 -0.5"/>
      <geometry>
        <capsule length="1.0" radius="0.02"/>
      </geometry>
    </collision>
    <inertial>
      <mass value="1"/>
      <origin rpy="0 0 0" xyz="0 0 -0.5"/>
      <inertia ixx="0.087959" ixy="0" ixz="0" iyy="0.087959" iyz="0" izz="0.00019896"/>
    </inertial>
  </link>

  <!-- pendulum joint -->
  <joint name="pendulum_joint" type="revolute">
    <origin rpy="0 0 0" xyz="0 0 0"/>
    <parent link="base"/>
    <child link="pendulum_link"/>
    <axis xyz="0 1 0"/>
    <limit effort="2.0" velocity="8.0" lower="-3.1416" upper="3.1416"/>
  </joint>
  <transmission name="pendulum_transmission">
    <type>transmission_interface/SimpleTransmission</type>
    <joint name="pendulum_joint">
      <hardwareInterface>hardware_interface/PositionJointInterface</hardwareInterface>
    </joint>
    <actuator name="pendulum">
      <hardwareInterface>hardware_interface/PositionJointInterface</hardwareInterface>
      <mechanicalReduction>1</mechanicalReduction>
      <motorTorqueConstant>1</motorTorqueConstant>
    </actuator>
  </transmission>
</robot>
