<?xml version="1.0"?>

<robot name="pendulum">
  <mujoco>
    <compiler fusestatic="false" balanceinertia="true" discardvisual="false"/>
  </mujoco>

  <!-- nontrivial base link -->
  <link name="base">
    <inertial>
      <mass value="2"/>
      <origin rpy="0 0 0" xyz="0 0 0"/>
      <inertia ixx="1.0" ixy="0" ixz="0" iyy="1.0" iyz="0" izz="1.0"/>
    </inertial>
  </link>

  <!-- pendulum link -->
  <link name="pendulum_link">
    <visual name="pendulum_link_visual">
      <origin rpy="0 0 0" xyz="0 0 -0.5"/>
      <geometry>
        <cylinder length="1.0" radius="0.02"/>
      </geometry>
    </visual>
    <collision name="pendulum_link_collision">
      <origin rpy="0 0 0" xyz="0 0 -0.5"/>
      <geometry>
        <cylinder length="1.0" radius="0.02"/>
      </geometry>
    </collision>
    <inertial>
      <mass value="1"/>
      <origin rpy="0 0 0" xyz="0 0 -0.5"/>
      <inertia ixx="0.083433" ixy="0" ixz="0" iyy="0.083433" iyz="0" izz="0.0002"/>
    </inertial>
  </link>

  <!-- pendulum joint -->
  <joint name="pendulum_joint" type="revolute">
    <origin rpy="0 0 0" xyz="0 0 0"/>
    <parent link="base"/>
    <child link="pendulum_link"/>
    <axis xyz="0 0 1"/>
    <limit effort="2.0" velocity="8.0" lower="-3.1416" upper="3.1416"/>
  </joint>
</robot>