<mujoco model="pendulum">
  <worldbody>
    <body name="base" pos="0 0 1.5">
      <inertial pos="0 0 0" mass="2" diaginertia="0.00072 0.00072 0.00072"/>
      <geom name="base_visual" size="0.03" pos="0 0 0" type="sphere" 
            contype="0" conaffinity="0" group="1" density="0" rgba="0 1 0 1"/>
      <body name="pendulum_link" pos="0 0 0">
        <inertial pos="0 0 -0.5" mass="1" diaginertia="0.087959 0.087959 0.00019896"/>
        <joint name="pendulum_joint" pos="0 0 0" axis="0 1 0" />
        <geom name="pendulum_link_visual" size="0.02 0.5" pos="0 0 -0.5" 
              type="capsule" contype="0" conaffinity="0" group="1" density="0" 
              rgba="1 0 0 1"/>
      </body>
    </body>
  </worldbody>
  <actuator>
    <motor joint="pendulum_joint"/>
  </actuator>
</mujoco>
