<mujoco model="pendulum">
  <compiler angle="radian"/>
  <statistic meansize="0.250205" extent="1.0008" center="0 0 -0.5"/>
  <worldbody>
    <body name="base">
      <inertial pos="0 0 0" mass="2" diaginertia="1 1 1"/>
      <body name="pendulum_link">
        <inertial pos="0 0 -0.5" mass="1" diaginertia="0.083433 0.083433 0.0002"/>
        <joint name="pendulum_joint" pos="0 0 0" axis="0 0 1" range="-3.1416 3.1416"/>
        <geom name="pendulum_link_visual" size="0.02 0.5" pos="0 0 -0.5" type="cylinder" contype="0" conaffinity="0" group="1" density="0"/>
        <geom name="pendulum_link_collision" size="0.02 0.5" pos="0 0 -0.5" type="cylinder"/>
      </body>
    </body>
  </worldbody>
</mujoco>
